<?xml version="1.0"?>
<sdf version="1.6">
  <model name="bot_car">
    <link name="base_link">
      <gravity>0</gravity>
      <collision name='car_body_mesh_collision'>
        <pose frame="">-0.02 0 0.05 1.570795 -0 -3.14159</pose>
        <geometry>
          <mesh>
            <scale>1 1 1</scale>
            <uri>model://meshes/confetti/top_cover_two_cameras.STL</uri>
          </mesh>
        </geometry>
        <surface>
          <contact>
            <collide_bitmask>0x8000</collide_bitmask>
          </contact>
        </surface>
      </collision>
      <pose frame="">0 0 0 0 -0 0</pose>
      <visual name="base_link_fixed_joint_lump__chassis_visual">
        <pose frame="">0.09 0 0.03 0 -0 0</pose>
        <geometry>
          <mesh>
            <scale>1 1 1</scale>
            <uri>model://meshes/confetti/chassis.dae</uri>
          </mesh>
        </geometry>
      </visual>
      <visual name="base_link_fixed_joint_lump__car_body_link_visual_1">
        <pose frame="">-0.02 0 0.05 1.570795 -0 -3.14159</pose>
        <geometry>
          <mesh>
            <scale>1 1 1</scale>
            <uri>model://meshes/confetti/top_cover_two_cameras.STL</uri>
          </mesh>
        </geometry>
        <!-- 0x28 0x28 0x28 -->
        <material>
          <ambient>0.156 0.156 0.156 1</ambient>
          <diffuse>0.156 0.156 0.156 1</diffuse>
          <specular>0 0 0 1</specular>
          <emissive>0 0 0 1</emissive>
        </material>
      </visual>
      <visual name="base_link_fixed_joint_lump__zed_camera_link_visual_2">
        <pose frame="">0.163258 0 0.142787 -0 -0.261799 -3.14159</pose>
        <geometry>
          <mesh>
            <scale>1 1 1</scale>
            <uri>model://meshes/confetti/camera.dae</uri>
          </mesh>
        </geometry>
      </visual>
    </link>
    <link name="left_front_wheel">
      <gravity>0</gravity>
      <pose frame="">0.195 0.06 0.03 1.5708 -0 0</pose>
      <visual name="left_front_wheel_visual">
        <pose frame="">0 0 0 1.5708 -0 0</pose>
        <geometry>
          <mesh>
            <scale>1 1 1</scale>
            <uri>model://meshes/confetti/left_front_wheel.dae</uri>
          </mesh>
        </geometry>
      </visual>
    </link>
    <joint name="left_front_wheel_joint" type="revolute">
      <child>left_front_wheel</child>
      <parent>base_link</parent>
      <axis>
        <xyz>0 1 4e-06</xyz>
        <limit>
          <lower>-1e+16</lower>
          <upper>1e+16</upper>
        </limit>
        <dynamics>
          <spring_reference>0</spring_reference>
          <spring_stiffness>0</spring_stiffness>
        </dynamics>
        <use_parent_model_frame>1</use_parent_model_frame>
      </axis>
    </joint>
    <link name="left_rear_wheel">
      <gravity>0</gravity>
      <pose frame="">0 0.06 0.03 1.5708 -0 0</pose>
      <visual name="left_rear_wheel_visual">
        <pose frame="">0 0 0 1.5708 -0 0</pose>
        <geometry>
          <mesh>
            <scale>1 1 1</scale>
            <uri>model://meshes/confetti/left_rear_wheel.dae</uri>
          </mesh>
        </geometry>
      </visual>
    </link>
    <joint name="left_rear_wheel_joint" type="revolute">
      <child>left_rear_wheel</child>
      <parent>base_link</parent>
      <axis>
        <xyz>0 1 4e-06</xyz>
        <limit>
          <lower>-1e+16</lower>
          <upper>1e+16</upper>
        </limit>
        <dynamics>
          <spring_reference>0</spring_reference>
          <spring_stiffness>0</spring_stiffness>
        </dynamics>
        <use_parent_model_frame>1</use_parent_model_frame>
      </axis>
    </joint>
    <link name="right_front_wheel">
      <gravity>0</gravity>
      <pose frame="">0.195 -0.06 0.03 1.5708 -0 0</pose>
      <visual name="right_front_wheel_visual">
        <pose frame="">0 0 0 1.5708 -0 0</pose>
        <geometry>
          <mesh>
            <scale>1 1 1</scale>
            <uri>model://meshes/confetti/right_front_wheel.dae</uri>
          </mesh>
        </geometry>
      </visual>
    </link>
    <joint name="right_front_wheel_joint" type="revolute">
      <child>right_front_wheel</child>
      <parent>base_link</parent>
      <axis>
        <xyz>0 1 4e-06</xyz>
        <limit>
          <lower>-1e+16</lower>
          <upper>1e+16</upper>
        </limit>
        <dynamics>
          <spring_reference>0</spring_reference>
          <spring_stiffness>0</spring_stiffness>
        </dynamics>
        <use_parent_model_frame>1</use_parent_model_frame>
      </axis>
    </joint>
    <link name="right_rear_wheel">
      <gravity>0</gravity>
      <pose frame="">0 -0.06 0.03 1.5708 -0 0</pose>
      <visual name="right_rear_wheel_visual">
        <pose frame="">0 0 0 1.5708 -0 0</pose>
        <geometry>
          <mesh>
            <scale>1 1 1</scale>
            <uri>model://meshes/confetti/right_rear_wheel.dae</uri>
          </mesh>
        </geometry>
      </visual>
    </link>
    <joint name="right_rear_wheel_joint" type="revolute">
      <child>right_rear_wheel</child>
      <parent>base_link</parent>
      <axis>
        <xyz>0 1 4e-06</xyz>
        <limit>
          <lower>-1e+16</lower>
          <upper>1e+16</upper>
        </limit>
        <dynamics>
          <spring_reference>0</spring_reference>
          <spring_stiffness>0</spring_stiffness>
        </dynamics>
        <use_parent_model_frame>1</use_parent_model_frame>
      </axis>
    </joint>
  </model>
</sdf>