<?xml version="1.0"?>
<sdf version="1.6">
  <model name="bot_car">
    <link name="base_link" >
      <gravity>0</gravity>
    </link>
    <link name="chassis">
      <gravity>0</gravity>
    </link>
    <joint name="base_link_joint" type="fixed">
      <parent>base_link</parent>
      <child>chassis</child>
    </joint>
    <link name="left_rear_wheel">
      <gravity>0</gravity>
      <visual name="left_rear_wheel_visual">
        <pose frame="">-0.081663 0.08105 0.038999 0 0 0</pose>
        <geometry>
          <mesh>
            <scale>1 1 1</scale>
            <uri>model://meshes/deepracer/left_rear_wheel.STL</uri>
          </mesh>
        </geometry>
        <material>
          <ambient>0.1 0.1 0.1 1</ambient>
          <diffuse>0.1 0.1 0.1 1</diffuse>
          <specular>0 0 0 1</specular>
          <emissive>0 0 0 1</emissive>
        </material>
      </visual>
    </link>
    <joint name="left_rear_wheel_joint" type="continuous">
      <parent>chassis</parent>
      <child>left_rear_wheel</child>
      <axis>
        <xyz>0 1 0</xyz>
      </axis>
      <use_parent_model_frame>1</use_parent_model_frame>
    </joint>
    <link name="right_rear_wheel">
      <gravity>0</gravity>
      <visual name="right_rear_wheel_visual">
        <pose frame="">-0.081663 -0.08105 0.038999 0 0 0</pose>
        <geometry>
          <mesh>
            <scale>1 1 1</scale>
            <uri>model://meshes/deepracer/right_rear_wheel.STL</uri>
          </mesh>
        </geometry>
        <material>
          <ambient>0.1 0.1 0.1 1</ambient>
          <diffuse>0.1 0.1 0.1 1</diffuse>
          <specular>0 0 0 1</specular>
          <emissive>0 0 0 1</emissive>
        </material>
      </visual>
    </link>
    <joint name="right_rear_wheel_joint" type="continuous">
      <parent>chassis</parent>
      <child>right_rear_wheel</child>
      <axis>
        <xyz>0 1 0</xyz>
      </axis>
      <use_parent_model_frame>1</use_parent_model_frame>
    </joint>

    <link name="left_front_wheel">
      <gravity>0</gravity>
      <visual name="left_front_wheel_visual">
        <pose frame="">0.082311 0.079601 0.027509 0 0 0</pose>
        <geometry>
          <mesh>
            <scale>1 1 1</scale>
            <uri>model://meshes/deepracer/left_front_wheel.STL</uri>
          </mesh>
        </geometry>
        <material>
          <ambient>0.1 0.1 0.1 1</ambient>
          <diffuse>0.1 0.1 0.1 1</diffuse>
          <specular>0 0 0 1</specular>
          <emissive>0 0 0 1</emissive>
        </material>
      </visual>
    </link>
    <joint name="left_front_wheel_joint" type="continuous">
      <parent>chassis</parent>
      <child>left_front_wheel</child>
      <axis>
        <xyz>0 1 0</xyz>
      </axis>
      <use_parent_model_frame>1</use_parent_model_frame>
    </joint>
    <link name="right_front_wheel">
      <gravity>0</gravity>
      <visual name="right_front_wheel_visual">
        <pose frame="">0.082311 -0.079601 0.027509 0 0 0</pose>
        <geometry>
          <mesh>
            <scale>1 1 1</scale>
            <uri>model://meshes/deepracer/right_front_wheel.STL</uri>
          </mesh>
        </geometry>
        <material>
          <ambient>0.1 0.1 0.1 1</ambient>
          <diffuse>0.1 0.1 0.1 1</diffuse>
          <specular>0 0 0 1</specular>
          <emissive>0 0 0 1</emissive>
        </material>
      </visual>
    </link>
    <joint name="right_front_wheel_joint" type="continuous">
      <parent>chassis</parent>
      <child>right_front_wheel</child>
      <axis>
        <xyz>0 1 0</xyz>
      </axis>
      <use_parent_model_frame>1</use_parent_model_frame>
    </joint>
    <link name="car_body_link_v3">
      <gravity>0</gravity>
      <visual name="car_body_link_v3_visual">
        <pose frame="">-0.0762 0 0.01577 0 0 0</pose>
        <geometry>
          <mesh>
            <scale>1 1 1</scale>
            <uri>model://meshes/deepracer/car_body_link_v3.STL</uri>
          </mesh>
        </geometry>
        <!-- 0x28 0x28 0x28 -->
        <material>
          <ambient>0.156 0.156 0.156 1</ambient>
          <diffuse>0.156 0.156 0.156 1</diffuse>
          <specular>0 0 0 1</specular>
          <emissive>0 0 0 1</emissive>
        </material>
      </visual>
      <collision name='car_body_link_v3_collision'>
        <pose frame="">-0.0762 0 0.01577 0 0 0</pose>
        <geometry>
          <mesh>
            <scale>1 1 1</scale>
            <uri>model://meshes/deepracer/car_body_link_v3.STL</uri>
          </mesh>
        </geometry>
        <surface>
          <contact>
            <collide_bitmask>0x8000</collide_bitmask>
          </contact>
        </surface>
      </collision>
    </link>
    <joint name="car_body_joint" type="fixed">
      <parent>chassis</parent>
      <child>car_body_link_v3</child>
      <axis>
        <xyz>0 0 0</xyz>
      </axis>
      <use_parent_model_frame>1</use_parent_model_frame>
    </joint>
  </model>
</sdf>